[TOC]

------

<center><font size=7><b>JavaScript错误处理</center></font></center>

---



## "try...catch"

通常，如果发生错误，脚本就会“死亡”（立即停止），并在控制台将错误打印出来。

`try...catch`，可以“捕获（catch）”错误，因此脚本可以执行更合理的操作，而不是死掉。



### 基本语法与工作方式

```javascript
try {

  // 代码...

} catch (err) {

  // 错误捕获

}
```

它按照以下步骤执行：

1. 首先，执行 `try {...}` 中的代码。
2. 如果这里没有错误，则忽略 `catch (err)`：执行到 `try` 的末尾并跳过 `catch` 继续执行。
3. 如果这里出现错误，则 `try` 执行停止，控制流转向 `catch (err)` 的开头。变量 `err`（我们可以使用任何名称）将包含一个 error 对象，该对象包含了所发生事件的详细信息。

![image-20240924152353235](https://raw.githubusercontent.com/Jenlybein/My-Typora-Images/imgs/202409241524577.png)



### 错误分为两类

- “解析（parse-time）错误
- 运行时的错误（runtime errors） 或  异常（exceptions）

**`try...catch` 仅对运行时的 error 有效**

要使得 `try...catch` 能工作，代码必须是可执行的。换句话说，它必须是有效的 JavaScript 代码。

如果代码包含语法错误，那么 `try..catch` 将无法正常工作

JavaScript 引擎首先会读取代码，然后运行它。在读取阶段发生的错误被称为“解析时间（parse-time）”错误，并且无法恢复（从该代码内部）。

`try...catch` 只能处理有效代码中出现的错误。这类错误被称为“运行时的错误（runtime errors）”，有时被称为“异常（exceptions）”。



### try...catch 同步执行

如果在“计划的（scheduled）”代码中发生异常，例如在 `setTimeout` 中，则 `try...catch` 不会捕获到异常：

```javascript
try {
  setTimeout(function() {
    noSuchVariable; // 脚本将在这里停止运行
  }, 1000);
} catch (err) {
  alert( "不工作" );
}
```

因为 `try...catch` 包裹了计划要执行的函数，该函数本身要稍后才执行，这时引擎已经离开了 `try...catch` 结构。

为了捕获到计划的（scheduled）函数中的异常，那么 `try...catch` 必须在这个函数内：

```javascript
setTimeout(function() {
  try {
    noSuchVariable; // try...catch 处理 error 了！
  } catch {
    alert( "error 被在这里捕获了！" );
  }
}, 1000);
```





## Error 对象

发生错误时，JavaScript 会生成一个包含有关此 error 详细信息的对象。然后将该对象作为参数传递给 `catch`：

```javascript
try {
  // ...
} catch (err) { // <-- “error 对象”，也可以用其他参数名代替 err
  // ...
}
```

对于所有内建的 error，error 对象具有两个主要属性：

- `name`

  Error 名称。例如，对于一个未定义的变量，名称是 `"ReferenceError"`。

- `message`

  关于 error 的详细文字描述。

还有其他非标准的属性在大多数环境中可用。其中被最广泛使用和支持的是：

- `stack`

  当前的调用栈：用于调试目的的一个字符串，其中包含有关导致 error 的嵌套调用序列的信息。

```javascript
try {
  lalala; // error, variable is not defined!
} catch (err) {
  alert(err.name); // ReferenceError
  alert(err.message); // lalala is not defined
  alert(err.stack); // ReferenceError: lalala is not defined at (...call stack)

  // 也可以将一个 error 作为整体显示出来
  // error 信息被转换为像 "name: message" 这样的字符串
  alert(err); // ReferenceError: lalala is not defined
}
```





## 可选的 “catch” 绑定

**最近新增的特性** ：这是一个最近添加到 JavaScript 的特性。 旧式浏览器可能需要 polyfills.

如果我们不需要 error 的详细信息，`catch` 也可以忽略它：

```javascript
try {
  // ...
} catch { // <-- 没有 (err)
  // ...
}
```





## 抛出 error

### "throw” 操作符"

`throw` 操作符会生成一个 error 对象。

```javascript
throw <error object>
```

技术上讲，我们可以将任何东西用作 error 对象。甚至可以是一个原始类型数据，例如数字或字符串，但最好使用对象，最好使用具有 `name` 和 `message` 属性的对象（某种程度上保持与内建 error 的兼容性）。

JavaScript 中有很多内建的标准 error 的构造器：`Error`，`SyntaxError`，`ReferenceError`，`TypeError` 等。我们也可以使用它们来创建 error 对象。

它们的语法是：

```javascript
let error = new Error(message);
// 或
let error = new SyntaxError(message);
let error = new ReferenceError(message);
// ...
```

对于内建的 error（不是对于其他任何对象，仅仅是对于 error），`name` 属性刚好就是构造器的名字。`message` 则来自于参数（argument）。

例如：

```javascript
let error = new Error("Things happen o_O");

alert(error.name); // Error
alert(error.message); // Things happen o_O
```



### 再次抛出（Rethrowing）

我们使用 `try...catch` 来处理不正确的数据。但是在 `try {...}` 块中是否可能发生 **另一个预料之外的 error**？

例如编程错误（未定义变量）或其他错误，而不仅仅是这种“不正确的数据”。

为了避免此类问题，我们可以采用“重新抛出”技术。规则很简单：

**`catch` 应该只处理它知道的 error，并“抛出”所有其他 error。**

“再次抛出（rethrowing）”技术可以被更详细地解释为：

1. Catch 捕获所有 error。
2. 在 `catch (err) {...}` 块中，我们对 error 对象 `err` 进行分析。
3. 如果我们不知道如何处理它，那我们就 `throw err`。

通常，我们可以使用 `instanceof` 操作符判断错误类型：

```javascript
try {
  user = { /*...*/ };
} catch (err) {
  if (err instanceof ReferenceError) {
    alert('ReferenceError'); // 访问一个未定义（undefined）的变量产生了 "ReferenceError"
  }
}
```

我们还可以从 `err.name` 属性中获取错误的类名。所有原生的错误都有这个属性。另一种方式是读取 `err.constructor.name`。





> 像这样，这个 `json` 在语法上是正确的，但是没有所必须的 `name` 属性该怎么办？
>
> ```javascript
> let json = '{ "age": 30 }'; // 不完整的数据
> 
> try {
> 
>     let user = JSON.parse(json); // <-- 没有 error
>     alert( user.name ); // 没有 name！
> 
> } catch (err) {
>     alert( "doesn't execute" );
> }
> ```
>
> 这里 `JSON.parse` 正常执行，但缺少 `name` 属性对我们来说确实是个 error。
>
> 让我们抛出这个 error。
>
> ```javascript
> let json = '{ "age": 30 }'; // 不完整的数据
> 
> try {
> 
>     let user = JSON.parse(json); // <-- 没有 error
> 
>     if (!user.name) {
>         throw new SyntaxError("数据不全：没有 name"); // (*)
>     }
> 
>     alert( user.name );
> 
> } catch(err) {
>     if (err instanceof SyntaxError) {
>         alert( "JSON Error: " + err.message );
>     } else {
>         throw err; // 再次抛出 (**)
>     }
> }
> ```
>
> 在 `(*)` 标记的这一行，`throw` 操作符生成了包含着我们所给定的 `message` 的 `SyntaxError`，与 JavaScript 自己生成的方式相同。`try` 的执行立即停止，控制流转向 `catch` 块。
>
> 现在，`catch` 成为了所有 error 处理的唯一场所：对于 `JSON.parse` 和其他情况都适用。
>
> 在上面的代码中，我们使用“再次抛出”，以达到在 `catch` 中只处理 `SyntaxError` 的目的。
>
> 如果 `(**)` 标记的这行 `catch` 块中的 error 从 `try...catch` 中“掉了出来”，那么它也可以被外部的 `try...catch` 结构（如果存在）捕获到，如果外部不存在这种结构，那么脚本就会被杀死。
>
> 所以，`catch` 块实际上只处理它知道该如何处理的 error，并“跳过”所有其他的 error。
>
> 下面这个示例演示了这种类型的 error 是如何被另外一级 `try...catch` 捕获的：
>
> ```javascript
> function readData() {
>   let json = '{ "age": 30 }';
> 
>   try {
>     // ...
>     blabla(); // error!
>   } catch (err) {
>     // ...
>     if (!(err instanceof SyntaxError)) {
>       throw err; // 再次抛出（不知道如何处理它）
>     }
>   }
> }
> 
> try {
>   readData();
> } catch (err) {
>   alert( "External catch got: " + err ); // 捕获了它！
> }
> ```
>
> 上面这个例子中的 `readData` 只知道如何处理 `SyntaxError`，而外部的 `try...catch` 知道如何处理任意的 error。



## try…catch…finally

该扩展语法如下所示：

```javascript
try {
   ... 尝试执行的代码 ...
} catch (err) {
   ... 处理 error ...
} finally {
   ... 总是会执行的代码 ...
}
```

`finally` 子句（clause）通常用在：当我们开始做某事的时候，希望无论出现什么情况都要完成某个任务。





## 全局 catch

设想一下，在 `try...catch` 结构外有一个致命的 error，然后脚本死亡了。

我们可能想要记录这个 error，并向用户显示某些内容（通常用户看不到错误信息）等。

规范中没有相关内容，但是代码的执行环境一般会提供这种机制，因为它确实很有用。例如，Node.JS 有 [`process.on("uncaughtException")`](https://nodejs.org/api/process.html#process_event_uncaughtexception)。在浏览器中，我们可以将一个函数赋值给特殊的 [window.onerror](https://developer.mozilla.org/zh/docs/Web/API/GlobalEventHandlers/onerror) 属性，该函数将在发生未捕获的 error 时执行。



```javascript
window.onerror = function(message, url, line, col, error) {
  // ...
};
```

- `message`

  error 信息。

- `url`

  发生 error 的脚本的 URL。

- `line`，`col`

  发生 error 处的代码的行号和列号。

- `error`

  error 对象。

> 例如：
>
> ```html
> <script>
>   window.onerror = function(message, url, line, col, error) {
>     alert(`${message}\n At ${line}:${col} of ${url}`);
>   };
> 
>   function readData() {
>     badFunc(); // 啊，出问题了！
>   }
> 
>   readData();
> </script>
> ```

全局错误处理程序 `window.onerror` 的作用通常不是恢复脚本的执行 —— 如果发生编程错误，恢复脚本的执行几乎是不可能的，它的作用是将错误信息发送给开发者。

也有针对这种情况提供 error 日志的 Web 服务，例如 [https://errorception.com](https://errorception.com/) 或 [http://www.muscula.com](http://www.muscula.com/)。

它们会像这样运行：

1. 我们注册该服务，并拿到一段 JavaScript 代码（或脚本的 URL），然后插入到页面中。
2. 该 JavaScript 脚本设置了自定义的 `window.onerror` 函数。
3. 当发生 error 时，它会发送一个此 error 相关的网络请求到服务提供方。
4. 我们可以登录到服务方的 Web 界面来查看这些 error。





## 自定义 Error

当我们在开发某些东西时，经常会需要我们自己的 error 类来反映在我们的任务中可能出错的特定任务。

我们自定义的 error 应该支持基本的 error 的属性，例如 `message`，`name`，并且最好还有 `stack`。

JavaScript 允许将 `throw` 与任何参数一起使用，所以从技术上讲，我们自定义的 error 不需要从 `Error` 中继承。但是，如果我们继承，那么就可以使用 `obj instanceof Error` 来识别 error 对象。因此，最好继承它。

随着开发的应用程序的增长，我们自己的 error 自然会形成形成一个层次结构（hierarchy）。
例如，`HttpTimeoutError` 可能继承自 `HttpError`，等等。



`Error` 类是内建的，但我们可以通过下面这段近似代码理解我们要扩展的内容：

```javascript
// JavaScript 自身定义的内建的 Error 类的“伪代码”
class Error {
  constructor(message) {
    this.message = message;
    this.name = "Error"; // (不同的内建 error 类有不同的名字)
    this.stack = <call stack>; // 非标准的，但大多数环境都支持它
  }
}
```



### 扩展 Error

例如，让我们考虑一个函数 `readUser(json)`，该函数应该读取带有用户数据的 JSON。

可用的 `json` 应带有 name 、age 属性。

在函数内部，我们将使用 `JSON.parse`。如果它接收到格式不正确的 `json`，就会抛出 `SyntaxError`。但是，即使 `json` 在语法上是正确的，也不意味着该数据是有效的用户数据。

函数 `readUser(json)` 不仅会读取 JSON，还会检查（“验证”）数据。如果没有所必须的字段，或者（字段的）格式错误，那么就会出现一个 error。我们称之为 `ValidationError`，并为之创建一个类，继承自 `Error` 类。这种类型的错误也应该包含有关违规字段的信息。

```javascript
class ValidationError extends Error {
  constructor(message) {
    super(message); // (1)
    this.name = "ValidationError"; // (2)
  }
}
```

请注意：在 `(1)` 行中我们调用了父类的 constructor。JavaScript 要求我们在子类的 constructor 中调用 `super`，所以这是必须的。父类的 constructor 设置了 `message` 属性。

父类的 constructor 还将 `name` 属性的值设置为了 `"Error"`，所以在 `(2)` 行中，我们将其重置为了右边的值。



尝试在 `readUser(json)` 中使用  `ValidationError`

```javascript
// 用法
function readUser(json) {
  let user = JSON.parse(json);

  if (!user.age) {
    throw new ValidationError("No field: age");
  }
  if (!user.name) {
    throw new ValidationError("No field: name");
  }

  return user;
}

// try..catch 的工作示例

try {
  let user = readUser('{ "age": 25 }');
} catch (err) {
  if (err instanceof ValidationError) {
    alert("Invalid data: " + err.message); // Invalid data: No field: name
  } else if (err instanceof SyntaxError) { // (*)
    alert("JSON Syntax Error: " + err.message);
  } else {
    throw err; // 未知的 error，再次抛出 (**)
  }
}
```

上面代码中的 `try..catch` 块既处理我们的 `ValidationError` 又处理来自 `JSON.parse` 的内建 `SyntaxError`。



### 深入继承

`ValidationError` 类是非常通用的。很多东西都可能出错。对象的属性可能缺失或者属性可能有格式错误（例如 `age` 属性的值为一个字符串而不是数字）。让我们针对缺少属性的错误来制作一个更具体的 `PropertyRequiredError` 类。它将携带有关缺少的属性的相关信息。

```javascript
class ValidationError extends Error {
  constructor(message) {
    super(message);
    this.name = "ValidationError";
  }
}

class PropertyRequiredError extends ValidationError {
  constructor(property) {
    super("No property: " + property);
    this.name = "PropertyRequiredError";
    this.property = property;
  }
}

// 用法
function readUser(json) {
  let user = JSON.parse(json);

  if (!user.age) {
    throw new PropertyRequiredError("age");
  }
  if (!user.name) {
    throw new PropertyRequiredError("name");
  }

  return user;
}

// try..catch 的工作示例

try {
  let user = readUser('{ "age": 25 }');
} catch (err) {
  if (err instanceof ValidationError) {
    alert("Invalid data: " + err.message); // Invalid data: No property: name
    alert(err.name); // PropertyRequiredError
    alert(err.property); // name
  } else if (err instanceof SyntaxError) {
    alert("JSON Syntax Error: " + err.message);
  } else {
    throw err; // 未知 error，将其再次抛出
  }
}
```

这个新的类 `PropertyRequiredError` 使用起来很简单：我们只需要传递属性名：`new PropertyRequiredError(property)`。人类可读的 `message` 是由 constructor 生成的。



请注意，在 `PropertyRequiredError` constructor 中的 `this.name` 是通过手动重新赋值的。这可能会变得有些乏味 —— 在每个自定义 error 类中都要进行 `this.name = <class name>` 赋值操作。我们可以通过创建自己的“基础错误（basic error）”类来避免这种情况，该类进行了 `this.name = this.constructor.name` 赋值。然后让所有我们自定义的 error 都从这个“基础错误”类进行继承。

让我们称之为 `MyError`。

这是带有 `MyError` 以及其他自定义的 error 类的代码，已进行简化：

```javascript
class MyError extends Error {
  constructor(message) {
    super(message);
    this.name = this.constructor.name;
  }
}

class ValidationError extends MyError { }

class PropertyRequiredError extends ValidationError {
  constructor(property) {
    super("No property: " + property);
    this.property = property;
  }
}

// name 是对的
alert( new PropertyRequiredError("field").name ); // PropertyRequiredError
```

现在自定义的 error 短了很多，特别是 `ValidationError`，因为我们摆脱了 constructor 中的 `"this.name = ..."` 这一行。



## 包装异常

如果 `readUser` 函数会产生多种 error，那么我们通常都不想每次都检查所有的 error 类型。

我们只想知道这里是否是“数据读取异常” —— 为什么发生了这样的 error 通常是无关紧要的（error 信息描述了它）。或者，如果我们有一种方式能够获取 error 的详细信息那就更好了，但前提是我们需要。



我们所描述的这项技术被称为“**包装异常**”。

1. 我们将创建一个新的类 `ReadError` 来表示一般的“数据读取” error。
2. 函数`readUser` 将捕获内部发生的数据读取 error，例如 `ValidationError` 和 `SyntaxError`，并生成一个 `ReadError` 来进行替代。
3. 对象 `ReadError` 会把对原始 error 的引用保存在其 `cause` 属性中。

之后，调用 `readUser` 的代码只需要检查 `ReadError`，而不必检查每种数据读取 error。并且，如果需要更多 error 细节，那么可以检查 `readUser` 的 `cause` 属性。

下面的代码定义了 `ReadError`，并在 `readUser` 和 `try..catch` 中演示了其用法：

```javascript
class ReadError extends Error {
  constructor(message, cause) {
    super(message);
    this.cause = cause;
    this.name = 'ReadError';
  }
}

class ValidationError extends Error { /*...*/ }
class PropertyRequiredError extends ValidationError { /* ... */ }

function validateUser(user) {
  if (!user.age) {
    throw new PropertyRequiredError("age");
  }

  if (!user.name) {
    throw new PropertyRequiredError("name");
  }
}

function readUser(json) {
  let user;

  try {
    user = JSON.parse(json);
  } catch (err) {
    if (err instanceof SyntaxError) {
      throw new ReadError("Syntax Error", err);
    } else {
      throw err;
    }
  }

  try {
    validateUser(user);
  } catch (err) {
    if (err instanceof ValidationError) {
      throw new ReadError("Validation Error", err);
    } else {
      throw err;
    }
  }

}

try {
  readUser('{bad json}');
} catch (e) {
  if (e instanceof ReadError) {
    alert(e);
    // Original error: SyntaxError: Unexpected token b in JSON at position 1
    alert("Original error: " + e.cause);
  } else {
    throw e;
  }
}
```

在上面的代码中，`readUser` 正如所描述的那样正常工作 —— 捕获语法和验证（validation）错误，并抛出 `ReadError`（对于未知错误将照常再次抛出）。

所以外部代码检查 `instanceof ReadError`，并且它的确是。不必列出所有可能的 error 类型。

这种方法被称为“包装异常（wrapping exceptions）”，因为我们将“低级别”的异常“包装”到了更抽象的 `ReadError` 中。它被广泛应用于面向对象的编程中。